Workbook

Sheet Read me
A1: Site artifacts: mapping workbook
A2: Everything compiled so far, for deciding what goes in each section. Nothing here is on the site yet.
A3: Direction (the most important thing)
A4: This is not a resume on a website. It should feel like: "This is Grant. Here are the things he's built, the places he's been, the problems he's worked on, the photos he's taken, and the weird side projects he makes because he's curious."
A5: Show, don't tell: the projects, photography, travel, languages, sports, startup and apps prove builder, field-oriented, problem solver, internationally curious and active. Don't add more personality words.
A6: Keep it uncluttered: personal context supports the work quietly, it never crowds it.
A7: Latest decisions: one quiet line in About ("Based in Austin · English, Italian, learning Portuguese"), with Jaylee and Helga as one small sprite each sitting on the 2021 ring (not a tile). No languages on the Travel map; no sports on films or trips. The Travel map is small dots (lived, photos, worked; homes you also worked in get the worked square, Wilmette is marked born), lines only for the moves between places lived, the countries visited shaded, and it zooms and pans.
A10: Sheets
A11: Artifacts: every project, role, app, build, film and place, with the section mapping.
A12: Section summary: counts per section (formulas) against a target, so you can see where to trim or add.
A13: Places: lived vs work sites vs trips, with map coordinates.
A14: Films: the 35mm albums with photo counts.
... A29: Resume and Portfolio 2025 PDF (10 case studies), your apps table, your Google Photos 35mm albums, and your profile notes in chat. Featured? values are my first suggestions.

Sheet Artifacts
A1: ID | B1: Artifact | C1: Type | D1: Org / context | E1: Location | F1: Start | G1: End | H1: What it is | I1: Key facts & numbers | J1: Tools / tech | K1: Link | L1: About | M1: Engineering | N1: Projects | O1: Art | P1: Travel | Q1: Digital | R1: Featured? | S1: Visual form | T1: 3D model? | U1: Assets we have | V1: To verify / missing | W1: Source
A2: Career & milestones (About timeline)
A3: R1 | B3: Enovis: Sr. Project Engineer, Advanced Manufacturing Engineering | C3: Role | D3: Enovis Corp | E3: Austin, TX | F3: 2025 | G3: Present | H3: Owner rep and engineering lead for a new operations facility and additive manufacturing center. | I3: See E1–E2. Leads a cross-functional engineering group; GCs, architects, specialty vendors. | J3: Project management, construction management, commissioning | L3: ● | M3: ○ | R3: Yes | S3: Timeline card | T3: No | U3: Enovis logo (in repo) | V3: What can be shown publicly about Enovis work. | W3: Resume
A4: R2 | B4: MAPEI Corp: Project Engineering Manager | C4: Role | D4: MAPEI Corp | E4: Dallas, TX | F4: 2021 | G4: 2024 | H4: Industrial construction and manufacturing capital projects. | I4: >$30M of capital projects (mechanical, electrical, process piping, equipment). See E3–E7. | J4: SolidWorks, AutoCAD, MS Project, P&IDs | L4: ● | M4: ○ | R4: Yes | S4: Timeline card | T4: No | U4: Portfolio pages 4–5; MAPEI logo (in repo) | V4: Card shows both stints: Chicago 2018–19, Dallas 2021–24. | W4: Resume
A5: R3 | B5: MAPEI SpA: Project Engineer | C5: Role | D5: MAPEI SpA (HQ) | E5: Milan, Italy | F5: 2019 | G5: 2021 | H5: Trained across day-to-day manufacturing operations; capital projects; static mixing R&D. | I5: Supported design, prototyping and testing of new static mixing technology (became E6). | L5: ● | M5: ○ | P5: ○ | R5: Yes | S5: Timeline card + Milan on map | T5: No | U5: MAPEI logo (in repo) | V5: Any photos from Milan / the plant? | W5: Resume
A6: R4 | B6: MAPEI Corp: Junior Project Engineer | C6: Role | D6: MAPEI Corp | E6: Chicago, IL | F6: 2018 | G6: 2019 | H6: Technical studies and medium-scale capital projects for the Chicago site. | I6: Process improvement and infrastructure upgrades. | L6: ● | R6: No | S6: Timeline card | T6: No | U6: MAPEI logo (in repo) | V6: Shown on the MAPEI Corp card (R2) as its 2018–19 Chicago stint; still marks Chicago as "worked" on the map. | W6: Resume
A7: R5 | B7: AWC Industries: Mechanical Engineering Intern | C7: Role | D7: AWC Industries | E7: Chicago, IL | F7: 2016 | G7: 2016 | H7: Summer internship designing components and assemblies. | I7: Cut raw-material waste with design-for-manufacture parts; designed replacement parts to prevent downtime. | J7: SolidWorks | L7: ● | R7: No | S7: Timeline card | T7: No | U7: None | V7: Removed from the site (your call). | W7: Resume
A8: R6 | B8: B.S. Mechanical Engineering | C8: Education | D8: University of Kansas | E8: Lawrence, KS | F8: 2014 | G8: 2018 | H8: BSME. | I8: Formula SAE electric powertrain (U1); biomechanical research (U2); SAE and Society of Biomedical Engineering. | L8: ● | P8: ○ | R8: Yes | S8: Timeline card | T8: No | U8: KU School of Engineering image (used as the KU tile picture); small KU logo (in repo, not shown under the tile) | W8: Resume
A9: R7 | B9: PMP certification | C9: Certification | D9: PMI | H9: Project Management Professional. | L9: ● | R9: No | S9: Badge | T9: No | U9: None | V9: Not on the site (this is not a resume). | W9: Resume
A10: R8 | B10: HOA Board Director | C10: Leadership | D10: Mercer Square Condominium Association | H10: Board director for a condominium association. | L10: ○ | R10: No | S10: Line in About | T10: No | U10: None | V10: Not on the site (this is not a resume). | W10: Resume
A11: Professional engineering projects
A12: E1 | B12: Operations facility build-out (200K sq ft) | C12: Engineering project | D12: Enovis Corp | E12: Austin, TX | F12: 2025 | G12: Present | H12: End-to-end design and construction of a facility combining office, automated distribution, clean pack, sterilization and additive manufacturing, as owner rep. | I12: 200K sq ft; budget >$10M; major utilities, equipment integration, controls, life safety; next-phase expansion and capacity planning; lean / continuous improvement. | J12: Design-build delivery, commissioning, validation | L12: ○ | M12: ● | P12: ○ | R12: Yes | S12: Miniature diorama of the building | T12: Yes (generic massing, real proportions) | U12: Enovis logo (in repo); MPOC model (block massing at real proportions, six zones + mezzanine, from the updated plan; no rooms) + tile still + About hover turntable, in Lens v2. MPOC, CPS and the AM lab are one plant. | V12: Public-safe photos or layouts? NDA limits? | W12: Resume
A13: E2 | B13: Industrial additive manufacturing center (EBM + SLS) | C13: Engineering project | D13: Enovis Corp | E13: Austin, TX | F13: 2025 | G13: Present | H13: Built out an AM center with EBM and SLS systems for patient-specific implants. | I13: Utilities, equipment siting, install sequencing, material-flow layout, production validation; scalable workflows aligned with regulatory, quality and environmental standards. | J13: EBM, SLS, process validation | M13: ● | N13: ○ | R13: Yes | S13: Printer / lattice part | T13: Yes (shares the MPOC model, lab lit) | U13: Shares the MPOC 3D model, opening with the additive & subtractive manufacturing lab highlighted | V13: What can be shown (medical device confidentiality). | W13: Resume
A14: E3 | B14: Automated dry mix production plant | C14: Engineering project | D14: MAPEI | E14: Houston, TX | H14: Ground-up automated dry mix production and packaging plant. | I14: European / North American vendors; Italian electrical contractors for power and automation; air permitting and FAA approval; delivered on budget and schedule. | J14: SolidWorks, AutoCAD, P&IDs, commissioning | L14: ○ | M14: ● | N14: ○ | P14: ○ | R14: Yes | S14: Silo tower (strong hero) | T14: Yes (Grant's exterior model of MAPEI Houston, v12) | U14: Portfolio p.4: elevation, P&ID, 3D render, tower photo, interior photo. MAPEI Houston exterior model (GLB v12) live in Lens v2 (zones: silo & mixing tower, production & warehouse, offices, site), opens with the tower lit; tile still + About hover turntable; photo viewer: the Houston silo tower and the plant interior (portfolio p.4) | V14: Dates: placeholder for now (About shows it at ~March 2022). | W14: Portfolio 2025
A15: E4 | B15: Robotic palletizer and bag applicator | C15: Engineering project | D15: MAPEI | E15: Tempe, AZ | H15: Added automated robotic palletizing and bag application to an existing dry mix plant. | I15: Doubled the plant's total output capacity; removed two manual operations; prefab kept downtime minimal. | J15: SolidWorks, AutoCAD, MS Project | M15: ● | N15: ○ | R15: Yes | S15: Robot cell | T15: Have vendor render (portfolio) | U15: Cover picture: render of the robot cell on white (sent by Grant), framed 3:2; photo viewer: the robot lifting bags (portfolio p.4) | V15: Dates: placeholder for now. | W15: Portfolio 2025
A16: E5 | B16: Site development: 315K sq ft brownfield | C16: Engineering project | D16: MAPEI | E16: Houston, TX (from Dallas); same facility as E3 and E7 | H16: Turned a speculative brownfield building into a full production and distribution facility. | I16: 315K sq ft; design-build; vendor selection and contracts; multiple concurrent projects. | J16: MS Project, design-build | M16: ● | P16: ○ | R16: Yes | S16: Building / diorama | T16: Yes (shares the MAPEI Houston model) | U16: MAPEI Houston model; tile still from higher up, with the site | V16: Lived in Dallas, travelled to Houston for this project. Dates: placeholder. | W16: Portfolio 2025
A17: E6 | B17: In-line static mixing process | C17: Engineering project | D17: MAPEI | E17: Milan → Dallas, TX | F17: 2019 | H17: First production version of a new static mixing technology, prototyped in Milan and built in Dallas. | I17: Production time −35%; manual operations removed; enabled bulk material purchasing; equipment procured from Europe. | J17: European vendors, electromechanical contractors | M17: ● | N17: ○ | P17: ○ | R17: Yes | S17: Mixing skid (prototype → production story) | T17: Have CAD (render in portfolio) | U17: Photo viewer: the static mixer as installed and its piping drawing (portfolio p.5). Picture still a placeholder. | V17: Dates: placeholder for now. | W17: Portfolio 2025
A18: E7 | B18: Liquid admixtures plant expansion ($5M) | C18: Engineering project | D18: MAPEI | E18: Houston, TX (in the MAPEI Houston facility, with E3) | H18: Plant expansion introducing automated blending and bulk transfer systems to the Southern U.S. | I18: $5M; design, construction, commissioning and lifecycle management. | J18: Process automation | M18: ● | R18: Yes | S18: Process skid | T18: Yes (shares the MAPEI Houston model, plant building lit) | U18: MAPEI Houston model; tile still with the plant building lit | V18: Dates: placeholder for now. Where inside the building is the admixtures plant? | W18: Resume
A19: Startup: OnlyChargeEV
A20: S1 | B20: OnlyChargeEV | C20: Startup | D20: Founder | E20: Dallas, TX (Austin, Houston, San Antonio) | F20: 2022 | G20: 2024 | H20: Commercial EV charging service company across major Texas hubs. | I20: Partners: ChargePoint, Ford Pro, Xeal Energy, Verdek. Commercial, fleet and multifamily clients. Automated payments, accounting, compliance, estimating and proposals. | J20: CRM automation, email campaigns | L20: ○ | M20: ○ | N20: ● | P20: ○ | Q20: ○ | R20: Yes | S20: Charger pedestal + Texas map | T20: Generate (charger) | U20: Portfolio pp.2–3; OnlyChargeEV logo (in repo) | V20: Logo coming; use a lightning-bolt placeholder. | W20: Resume
A21: S1a | B21: FedEx Office HQ workplace charging | C21: EV install | D21: OnlyChargeEV | E21: Dallas, TX | H21: Modernized workplace charging for FedEx Office HQ. | I21: 8 Enel X JuiceBox Pro 40 L2 chargers on dual stands (4 replaced + 4 added = 8 ports); trenching, concrete, electrical; permits. | M21: ● | N21: ○ | R21: Maybe | S21: Case inside S1 | T21: No | U21: Portfolio p.2: site plan + photo | W21: Portfolio 2025
A22: S1b | B22: Stallion Infrastructure Services fleet charging | C22: EV install | D22: OnlyChargeEV | E22: Houston, TX | H22: Fleet charging across a company campus. | I22: 5 Ford Pro 11.5 kW (80A) wall-mounted L2 chargers; conduit, wiring, bollards; permitting. | M22: ● | N22: ○ | R22: Maybe | S22: Case inside S1 | T22: No | U22: Portfolio p.2: photos | W22: Portfolio 2025
A23: S1c | B23: University multi-use commercial garage | C23: EV install | D23: OnlyChargeEV | E23: Fort Worth, TX | H23: Residential charging in a new multifamily parking garage. | I23: 10 Xeal (32A) L2 chargers; power sharing to avoid electrical upgrades; commissioning. | M23: ● | N23: ○ | R23: Maybe | S23: Case inside S1 | T23: No | U23: Portfolio p.3: plan + photo | W23: Portfolio 2025
A24: S1d | B24: Gateway Cedars multifamily | C24: EV install | D24: OnlyChargeEV | E24: Dallas, TX | H24: Charging for a multifamily development. | I24: Two dual-port ChargePoint CT4000 units (4 ports); electrical upgrades; permitting. | M24: ● | N24: ○ | R24: Maybe | S24: Case inside S1 | T24: No | U24: Portfolio p.3: aerial plan + photo | W24: Portfolio 2025
A25: University projects
A26: U1 | B26: Formula SAE electric racecar | C26: University project | D26: University of Kansas | E26: Lawrence, KS | F26: 2017 | G26: 2018 | H26: Electric powertrain for KU's Formula SAE electric racecar. | I26: Led 5 electrical engineers; in-house motor controller; battery storage and management system; raced at Formula SAE Electric (Lincoln, NE). | J26: SolidWorks, MATLAB, FEA, 3D printing, CNC, laser, water jet | K26: Video: youtube.com/watch?v=QBBdbAZleAo | L26: ○ | M26: ○ | N26: ● | R26: Yes | S26: Racecar | T26: Have CAD (render in portfolio) | U26: Cover picture: Grant's render of the car; photo viewer: the nose in the rain (portfolio copy); video link | V26: CAD file? Race results? | W26: Portfolio 2025
A27: U2 | B27: Assistive piano-pedal device | C27: University project | D27: KU biomechanical research | E27: Lawrence, KS | F27: 2016 | G27: 2017 | H27: Assistive devices that let a paraplegic pianist operate piano pedals. | I27: Played piano pedals for the first time; two additive prototypes, final part machined; team of 4; national news coverage. | J27: SolidWorks, 3D printing, CNC | K27: Video: youtube.com/watch?v=KiA2okjlkbE · The Kansas City Star: kansascity.com/news/local/article217177885.html · KSHB 41: kshb.com/news/local-news/ku-engineering-students-create-device-to-help-change-the-tune-for-young-teen | L27: ○ | M27: ○ | N27: ● | R27: Yes | S27: Pedal device | T27: Yes (reconstruction from photos, GLB; exploded build) | U27: 3D model of the device live in Lens v2 (six part zones) + tile still + About hover turntable; 5 photos from the portfolio (device, with the pianist, in CAD, two CAD renders) in the photo viewer; video and two news links | V27: News links: dummy placeholders until you send real ones. | W27: Portfolio 2025
A28: Maker builds
A29: M1 | B29: Resin Light 1.0 | C29: Maker build | D29: Personal | H29: First functional prototype of the Resin Lights: illuminated art and lighting pieces that combine cast resin with integrated LED lighting, the resin acting as both the visual material and the diffuser, so the object glows instead of exposing a fixture. | I29: Built to test the concept and learn how materials, lighting and fabrication behave in practice: resin casting technique, mold design, LED placement, diffusion, brightness, heat management, structure, surface finish, assembly. | J29: Mold making, resin casting, LED integration, thermal and electrical design, fabrication, finishing | N29: ● | O29: ○ | R29: Yes | S29: Object photo or 3D | T29: Generate from photos | U29: None yet | V29: Photos coming. | W29: Chat
A30: M2 | B30: Resin Light 2.0 | C30: Maker build | D30: Personal | H30: Refined, high-fidelity, production-intent Resin Light, built on the lessons from 1.0. | I30: Improved form, lighting quality, material consistency, manufacturing process, repeatability, assembly, durability, fit and finish. Goal: move past a one-off prototype to a design that could realistically be manufactured and sold. | J30: Mold making, resin casting, LED integration, design for manufacture | N30: ● | O30: ○ | R30: Yes | S30: Object photo or 3D | T30: Generate from photos | U30: None yet | V30: Photos coming. | W30: Chat
A31: M3 | B31: LED wall art | C31: Maker build | D31: Personal | H31: A series of wall-mounted illuminated art pieces designed and fabricated from the ground up: concealed LEDs, layered structural components, diffusers and controlled spacing give a soft glow or gradient while hiding the electronics. | I31: Arduino-based controls, integrated circuit board, wired LEDs and a Bluetooth module, plus a custom app to control lighting behaviour, brightness and effects. | J31: Arduino, custom circuit board, Bluetooth, addressable LEDs, control app | M31: ○ | N31: ● | O31: ○ | Q31: ○ | R31: Yes | S31: Glowing panel | T31: Generate (simple) | U31: None yet | V31: Photos / video coming. | W31: Chat
A32: Apps & software
A33: A1 | B33: ContactFlow | C33: App | D33: Personal | F33: Oct 2026 | G33: Oct 2026 | H33: Contact discovery pipeline: paste messy people / company data, extract contacts, find domains, discover email patterns, rank candidates, verify domains, export CSV. | I33: Your rating: ⭐ Excellent | J33: TypeScript, React, Vite, Tailwind, Supabase, Claude | K33: https://contact-flow-web.vercel.app | Q33: ● | R33: Yes | S33: Screen with real screenshot | T33: No (screen) | U33: Live site; app icon (redrawn from your screenshot: send the original file) | V33: Screenshot / short screen recording. | W33: Apps table
A34: A2 | B34: JobPaper | C34: App | D34: Personal | F34: Oct 2026 | G34: Oct 2026 | H34: ChatGPT app that turns contractor notes and photos into estimates, change orders and job reports, with editable documents and PDF export. | I34: Your rating: ⭐ Excellent | J34: TypeScript, MCP, ChatGPT Apps, jsPDF, Vercel | K34: https://job-paper.vercel.app | M34: ○ | Q34: ● | R34: Yes | S34: Screen with real screenshot | T34: No (screen) | U34: Live site | V34: Screenshot / short screen recording. | W34: Apps table
A35: A3 | B35: Collateral Damage | C35: App | D35: Personal | F35: Sep 2026 | G35: Oct 2026 | H35: Interactive simulation explaining collateral-damage estimation with a paper city, Monte Carlo runs, adjustable strike parameters and population estimates. | I35: Your rating: ⭐ Excellent | J35: TypeScript, Vite, simulation workers | K35: https://collateral-damage.vercel.app | M35: ○ | O35: ○ | Q35: ● | R35: Yes | S35: Screen with real screenshot | T35: No (screen) | U35: Live site | V35: Screenshot / short screen recording. | W35: Apps table
A36: A4 | B36: Virtual Dog Playground | C36: App | D36: Personal | F36: Oct 2026 | G36: Oct 2026 | H36: Virtual backyard for Jaylee and Helga with animated sprites, needs, personalities, autonomous play, swimming, tug-of-war and AI chat. | I36: Your rating: ⭐ Excellent creative | J36: TypeScript, Claude, Vercel | K36: https://jaylee-app.vercel.app | L36: ○ | O36: ○ | Q36: ● | R36: No | S36: Screen with real screenshot | T36: No (screen) | U36: Live site | V36: OK to name Jaylee and Helga, with a photo. | W36: Apps table
A37: A5 | B37: Gradient UI / Atmos Studio | C37: App | D37: Personal | F37: Sep 2026 | G37: Sep 2026 | H37: Nature-inspired gradient studio: 87 curated gradients, mesh editing, weather effects, animation, Live Sky, photo palette extraction, AI generation. | I37: Your rating: ⭐ Excellent visual | J37: TypeScript, React, Vite, Supabase, Claude | K37: https://gradient-ui.vercel.app | O37: ○ | Q37: ● | R37: Yes | S37: Screen with real screenshot | T37: No (screen) | U37: Live site | V37: Screenshot / short screen recording. | W37: Apps table
A38: A6 | B38: GoldStarMan | C38: App | D38: Personal | F38: Jan 2026 | G38: Jan 2026 | H38: Goal and habit app built on yearly goals, weekly minimums and low-pressure daily progress instead of streaks. | I38: Your rating: Good | J38: Next.js 15, TypeScript, Tailwind | K38: https://gold-star-man.vercel.app | Q38: ● | R38: No | S38: Screen with real screenshot | T38: No (screen) | U38: Live site | V38: Screenshot / short screen recording. | W38: Apps table
A39: A7 | B39: Story AI (private) | C39: App | D39: Personal | F39: Nov 2025 (approx.) | G39: Nov 2025 | H39: Personalized children's story generator with character creation, story library, auth and an interactive reader. | I39: Your rating: Good | J39: Next.js 16, TypeScript, Supabase, Tailwind | Q39: ● | R39: No | S39: Screen with real screenshot | T39: No (screen) | U39: None yet | V39: Screenshots only (private). | W39: Apps table
A40: A8 | B40: AIConstruction | C40: App | D40: Personal | F40: Apr 2025 | G40: Jan 2026 | H40: Conversational DIY / construction assistant: recommends materials and tools, builds shopping lists, supports affiliate links. | I40: Your rating: Good | J40: Next.js, TypeScript, Tailwind, OpenAI | M40: ○ | Q40: ● | R40: No | S40: Screen with real screenshot | T40: No (screen) | U40: None yet | V40: Live link to add. | W40: Apps table
...

Sheet Section summary
A1: Section | B1: Main (●) | C1: Appears (● + ○) | D1: Featured (main + Yes) | E1: Target min | F1: Target max | G1: Status | H1: Note
A2: About | B2: =COUNTIF(Artifacts!$L$2:$L$124,"●") -> 7 | C2: =COUNTIF(Artifacts!$L$2:$L$124,"●")+COUNTIF(Artifacts!$L$2:$L$124,"○") -> 20 | D2: =COUNTIFS(Artifacts!$L$2:$L$124,"●",Artifacts!$R$2:$R$124,"Yes") -> 4 | E2: 6 | F2: 8 | G2: =IF(D2<E2,"Add",IF(D2>F2,"Trim","OK")) -> Add | H2: Milestones, not the whole archive.
A3: Engineering | B3: =COUNTIF(Artifacts!$M$2:$M$124,"●") -> 11 | C3: =COUNTIF(Artifacts!$M$2:$M$124,"●")+COUNTIF(Artifacts!$M$2:$M$124,"○") -> 24 | D3: =COUNTIFS(Artifacts!$M$2:$M$124,"●",Artifacts!$R$2:$R$124,"Yes") -> 7 | E3: 3 | F3: 7 | G3: =IF(D3<E3,"Add",IF(D3>F3,"Trim","OK")) -> OK | H3: Your picks: 7. E5 could pair with E3 (both Houston) if it feels busy.
A4: Projects | B4: =COUNTIF(Artifacts!$N$2:$N$124,"●") -> 6 | C4: =COUNTIF(Artifacts!$N$2:$N$124,"●")+COUNTIF(Artifacts!$N$2:$N$124,"○") -> 14 | D4: =COUNTIFS(Artifacts!$N$2:$N$124,"●",Artifacts!$R$2:$R$124,"Yes") -> 6 | E4: 4 | F4: 6 | G4: =IF(D4<E4,"Add",IF(D4>F4,"Trim","OK")) -> OK | H4: Builds and the startup.
A5: Art | B5: =COUNTIF(Artifacts!$O$2:$O$124,"●") -> 11 | C5: =COUNTIF(Artifacts!$O$2:$O$124,"●")+COUNTIF(Artifacts!$O$2:$O$124,"○") -> 17 | D5: =COUNTIFS(Artifacts!$O$2:$O$124,"●",Artifacts!$R$2:$R$124,"Yes") -> 11 | E5: 3 | F5: 12 | G5: =IF(D5<E5,"Add",IF(D5>F5,"Trim","OK")) -> OK | H5: All 11 films chosen, as stacks on the Art plot.
A6: Travel | B6: =COUNTIF(Artifacts!$P$2:$P$124,"●") -> 6 | C6: =COUNTIF(Artifacts!$P$2:$P$124,"●")+COUNTIF(Artifacts!$P$2:$P$124,"○") -> 24 | D6: =COUNTIFS(Artifacts!$P$2:$P$124,"●",Artifacts!$R$2:$R$124,"Yes") -> 6 | E6: 6 | F6: 12 | G6: =IF(D6<E6,"Add",IF(D6>F6,"Trim","OK")) -> OK | H6: Places lived + trips worth showing.
A7: Digital | B7: =COUNTIF(Artifacts!$Q$2:$Q$124,"●") -> 14 | C7: =COUNTIF(Artifacts!$Q$2:$Q$124,"●")+COUNTIF(Artifacts!$Q$2:$Q$124,"○") -> 16 | D7: =COUNTIFS(Artifacts!$Q$2:$Q$124,"●",Artifacts!$R$2:$R$124,"Yes") -> 7 | E7: 2 | F7: 6 | G7: =IF(D7<E7,"Add",IF(D7>F7,"Trim","OK")) -> Trim | H7: Strongest apps.
A9: Artifacts listed | B9: =COUNTA(Artifacts!$C$2:$C$124) -> 56
A11: Targets (blue) are my suggestions from our discussion: change them freely. "Featured" counts artifacts whose main section is this one and Featured? = Yes.

Sheet Places
A1: Place | B1: Country | C1: Kind | D1: From | E1: To | F1: Why | G1: Lat | H1: Lon | I1: Show on map? | J1: Note
A2: Wilmette, IL | B2: USA | C2: Lived | E2: 2014 | F2: Born / grew up | G2: 42.08 | H2: -87.72 | I2: Yes | J2: Confirmed: before Lawrence. Marked "born" on the map (phones say "Chicago · born")
A3: Lawrence, KS | B3: USA | C3: Lived | D3: 2014 | E3: 2018 | F3: University of Kansas | G3: 38.97 | H3: -95.24 | I3: Yes | J3: Confirmed
A4: Chicago, IL | B4: USA | C4: Lived / worked | D4: 2018 | E4: 2019 | F4: MAPEI Chicago | G4: 41.88 | H4: -87.63 | I4: Yes | J4: Confirmed
A5: Milan | B5: Italy | C5: Lived | D5: 2019 | E5: 2021 | F5: MAPEI SpA | G5: 45.46 | H5: 9.19 | I5: Yes | J5: Confirmed
A6: Dallas, TX | B6: USA | C6: Lived | D6: 2021 | E6: 2025 | F6: MAPEI Corp; OnlyChargeEV | G6: 32.78 | H6: -96.8 | I6: Yes | J6: Confirmed; until the Austin move (April 2025)
A7: Austin, TX | B7: USA | C7: Lives now | D7: 2025 | E7: Present | F7: Enovis | G7: 30.27 | H7: -97.74 | I7: Yes | J7: Since April 2025
A8: Houston, TX | B8: USA | C8: Work site | F8: MAPEI Houston, one facility: dry mix plant (E3), liquid admixtures plant (E7), site development (E5); Stallion EV (S1b) | G8: 29.76 | H8: -95.37 | I8: Maybe
A9: Tempe, AZ | B9: USA | C9: Work site | F9: Robotic palletizer (E4) | G9: 33.43 | H9: -111.94 | I9: Maybe
A10: Fort Worth, TX | B10: USA | C10: Work site | F10: Multifamily garage charging (S1c) | G10: 32.76 | H10: -97.33 | I10: No
A11: Lincoln, NE | B11: USA | C11: Event | D11: 2018 | E11: 2018 | F11: Formula SAE Electric competition | G11: 40.81 | H11: -96.7 | I11: No
A12: Mallorca, Ibiza & Formentera | B12: Spain | C12: Trip | D12: 2026 | E12: 2026 | F12: Film F1 | G12: 39.57 | H12: 2.65 | I12: Yes
A13: Lagos, Algarve & Lisbon | B13: Portugal | C13: Trip | D13: 2026 | E13: 2026 | F13: Film F2 | G13: 38.72 | H13: -9.14 | I13: Yes
A14: Argentina–Chile–Peru | B14: Argentina, Chile, Peru | C14: Trip | D14: 2025 | E14: 2025 | F14: Film F3 | I14: Yes | J14: Which cities?
A15: Mexico | B15: Mexico | C15: Trip | D15: 2025 | E15: 2025 | F15: Film F4 | I15: Yes | J15: Which cities?
A16: New Mexico | B16: USA | C16: Trip | D16: 2025 | E16: 2025 | F16: Film F5 (father & son) | I16: Yes | J16: Which cities?
A17: Brazil | B17: Brazil | C17: Trip | D17: 2024 | E17: 2024 | F17: Film F6 | G17: -22.97 | H17: -43.18 | I17: Yes | J17: Cover looks like Rio: verify
A18: Peru | B18: Peru | C18: Trip | D18: 2023 | E18: 2023 | F18: Film F7 | I18: Yes | J18: Which cities?
A19: Palm Beach, FL | B19: USA | C19: Trip | D19: 2023 | E19: 2023 | F19: Film F8 | G19: 26.71 | H19: -80.04 | I19: Maybe
A20: Mexico City | B20: Mexico | C20: Trip | D20: 2022 | E20: 2022 | F20: Film F9 | G20: 19.43 | H20: -99.13 | I20: Yes
A21: Italy | B21: Italy | C21: Trip | D21: 2021 | E21: 2021 | F21: Film F10 | G21: 41.89 | H21: 12.49 | I21: Yes | J21: Cover looks like Rome: verify
A22: Colombia | B22: Colombia | C22: Trip | D22: 2022 | E22: 2022 | F22: Film F11 | I22: Yes
A24: Lived vs travelled are kept separate. Countries visited (34) are on the Countries sheet and all shaded on the Travel map.
A25: Coordinates are approximate city centres for the map; blank where the city is unknown.

Sheet Films
A1: ID | B1: Album | C1: Place | D1: Year | E1: Photos | F1: Featured? | G1: Note
A2: F1 | B2: Mallorca, Ibiza & Formentera (35mm) | C2: Spain | D2: 2026 | E2: 65 | F2: Yes
A3: F2 | B3: Lagos, Algarve & Lisbon (35mm) | C3: Portugal | D3: 2026 | E3: 64 | F3: Yes
A4: F3 | B4: Argentina–Chile–Peru (35mm) | C4: Argentina, Chile, Peru | D4: 2025 | E4: 267 | F4: Yes
A5: F4 | B5: Mexico (35mm) | C5: Mexico | D5: 2025 | E5: 84 | F5: Yes
A6: F5 | B6: New Mexico (Father & Son) (35mm) | C6: New Mexico, USA | D6: 2025 | E6: 39 | F6: Yes
A7: F6 | B7: Brazil (35mm) | C7: Brazil | D7: 2024 | E7: 177 | F7: Yes
A8: F7 | B8: Peru (35mm) | C8: Peru | D8: 2023 | E8: 106 | F8: Yes
A9: F8 | B9: Palm Beach (35mm) | C9: Florida, USA | D9: 2023 | E9: 39 | F9: Yes
A10: F9 | B10: Mexico City (35mm) | C10: Mexico | D10: 2022 | E10: 59 | F10: Yes
A11: F10 | B11: Italy (35mm) | C11: Italy | D11: 2021 | E11: 59 | F11: Yes
A12: F11 | B12: Colombia (35mm) | C12: Colombia | D12: 2022 | E12: 53 | F12: Yes
D13: Total | E13: =SUM(E2:E12) -> 1012
D14: Featured | E14: =COUNTIF(F2:F12,"Yes") -> 11
A16: Photo counts come from your Google Photos screenshot. Each album becomes one print stack in Art and a trip on the Travel map.
A19: I hace them on google just add place holders viaul now we can give you folder or links later for the phtoos.

Sheet Countries
A1: # | B1: Country | C1: Region | D1: On the Travel map | E1: Note
A2: 1 | B2: USA | C2: North America | D2: Shaded
A3: 2 | B3: Canada | C3: North America | D3: Shaded
A4: 3 | B4: Mexico | C4: North America | D4: Shaded
A5: 4 | B5: Bahamas | C5: Caribbean | D5: Shaded
A6: 5 | B6: Dominican Republic | C6: Caribbean | D6: Shaded
A7: 6 | B7: Dominica | C7: Caribbean | D7: Dot | E7: Too small for the map outlines
A8: 7 | B8: St Lucia | C8: Caribbean | D8: Dot | E8: Too small for the map outlines
A9: 8 | B9: Barbados | C9: Caribbean | D9: Dot | E9: Too small for the map outlines
A10: 9 | B10: St Kitts | C10: Caribbean | D10: Dot | E10: Too small for the map outlines
A11: 10 | B11: Jamaica | C11: Caribbean | D11: Shaded
A12: 11 | B12: Belize | C12: Central America | D12: Shaded
A13: 12 | B13: Honduras | C13: Central America | D13: Shaded
A14: 13 | B14: Panama | C14: Central America | D14: Shaded
A15: 14 | B15: Guatemala | C15: Central America | D15: Shaded
A16: 15 | B16: Colombia | C16: South America | D16: Shaded | E16: Film F11
A17: 16 | B17: Peru | C17: South America | D17: Shaded | E17: Films F3, F7
A18: 17 | B18: Brazil | C18: South America | D18: Shaded | E18: Film F6
A19: 18 | B19: Argentina | C19: South America | D19: Shaded | E19: Film F3
A20: 19 | B20: Chile | C20: South America | D20: Shaded | E20: Film F3
A21: 20 | B21: South Africa | C21: Africa | D21: Shaded
A22: 21 | B22: Spain | C22: Europe | D22: Shaded | E22: Film F1
A23: 22 | B23: Portugal | C23: Europe | D23: Shaded | E23: Film F2
A24: 23 | B24: Italy | C24: Europe | D24: Shaded | E24: Lived (Milan); film F10
A25: 24 | B25: Slovenia | C25: Europe | D25: Shaded
A26: 25 | B26: France | C26: Europe | D26: Shaded
A27: 26 | B27: Croatia | C27: Europe | D27: Shaded
A28: 27 | B28: Hungary | C28: Europe | D28: Shaded
A29: 28 | B29: Czech Republic | C29: Europe | D29: Shaded
A30: 29 | B30: Germany | C30: Europe | D30: Shaded
A31: 30 | B31: Switzerland | C31: Europe | D31: Shaded
A32: 31 | B32: Denmark | C32: Europe | D32: Shaded
A33: 32 | B33: England (UK) | C33: Europe | D33: Shaded
A34: 33 | B34: Netherlands | C34: Europe | D34: Shaded
A35: 34 | B35: Austria | C35: Europe | D35: Shaded
B37: Total | C37: =COUNTA(B2:B35) -> 34
B38: Shaded | C38: =COUNTIF(D2:D35,"Shaded") -> 30
B39: Dot | C39: =COUNTIF(D2:D35,"Dot") -> 4
A41: Your list, 34 countries (count verified). Every one is on the Travel map: shaded, or a dot for the four islands too small for its outlines.

Sheet Profile
A1: Group | B1: Item | C1: Detail | D1: Use on site? | E1: Source
A2: Theme | B2: Builder | C2: Takes things from idea through design, construction, commissioning and real operation. | D2: Yes | E2: Your notes
A3: Theme | B3: Field-oriented engineer | C3: Comfortable on a site or factory floor; wants a tangible connection to what gets built. | D3: Yes | E3: Your notes
A4: Theme | B4: Problem solver | C4: Drawn to ambiguous situations: understand the system, work the constraints, find a path. | D4: Yes | E4: Your notes
A5: Theme | B5: Internationally curious | C5: Travel, living abroad, languages and cultures are central, not occasional. | D5: Yes | E5: Your notes
A6: Theme | B6: Active / adventurous | C6: Movement, outdoors, exploration, learning new physical skills. | D6: Yes | E6: Your notes
A7: Language | B7: English | C7: Native | D7: Yes | E7: Resume
A8: Language | B8: Italian | C8: Professional working proficiency | D8: Yes | E8: Resume
A9: Language | B9: Portuguese | C9: Learning | D9: Yes | E9: Your notes
A10: Personal | B10: Profile | C10: Deeply curious, adventurous, hands-on; likes unfamiliar problems and new environments; cultures and learning. | D10: Yes | E10: Your notes
A11: Interests | B11: Travel; film / photography | D11: Yes | E11: Your notes
A12: Interests | B12: Endurance | C12: Running, trail running, cycling / mountain biking, swimming, triathlons, hiking | D12: Yes | E12: Your notes
A13: Interests | B13: Board & water | C13: Snowboarding, surfing, kitesurfing | D13: Yes | E13: Your notes
A14: Interests | B14: Ball & racket | C14: Soccer, padel, pickleball, golf | D14: Yes | E14: Your notes
A15: Values | B15: Values | C15: Family and friends, curiosity, learning, exploration, independence, problem solving, physical activity, different cultures. | D15: Yes | E15: Your notes
A16: Industries | B16: Industries | C16: Manufacturing; construction materials / chemicals (MAPEI); medical devices and additive manufacturing (Enovis); EV infrastructure; industrial construction. | D16: Yes | E16: Resume
A17: Skills | B17: Management | C17: Project management, business development, budget planning, industrial construction, procurement, strategic planning, site integration, risk tracking, expansion planning, equipment installation & integration. | D17: Yes | E17: Resume
A18: Skills | B18: Technical | C18: Mechanical & electrical systems design, EV infrastructure, P&IDs, process automation, permits & compliance. | D18: Yes | E18: Resume
A19: Skills | B19: Engineering software | C19: AutoCAD, SolidWorks, MATLAB, LabVIEW, Microsoft Project, CRM / ERP. | D19: Yes | E19: Resume
A20: Skills | B20: Software (from app building) | C20: TypeScript, React, Next.js, Vite, Tailwind, Supabase, Python, Claude / OpenAI APIs, MCP, Llama fine-tuning, image segmentation. | D20: Yes | E20: Apps table
A21: Future | B21: Future interests | C21: (industries, locations, technologies, roles you want next) we can maybe add place for this with placeholder and ill add or deelte stuff | D21: Ask | E21: To fill
A22: Rule | B22: Resume facts vs personal context | C22: Keep personal context (family, sports, travel) out of anything resume-like unless chosen deliberately. | E22: Your notes
A23: Rule | B23: Show, don't tell | C23: No more personality words. The five themes are enough; the projects, photos, travel, languages, sports, startup and apps prove them. | E23: Your notes
A24: Rule | B24: One quiet line | C24: At most one line in About: "Based in Austin · English, Italian, learning Portuguese". Languages stay off the Travel map; sports stay off the films and trips. | E24: Your answer
A25: Personal | B25: Jaylee and Helga | C25: Named, as one small sprite of each sitting on the 2021 ring in About (name on hover), never as a tile. | D25: Yes | E25: Your answer
A26: not sure how to diplay all the about profle stuff don’t want to make everythign to busy also!! | B26: → Decided: the one quiet line and the dogs (rows 24–25). Everything else here is shown by the work itself, not listed.
A28: Race | B28: Austin Marathon | C28: Full marathon (26.2 mi), February 2024. Its logo, small, on the 2024 ring in About (name on hover). | D28: Yes | E28: Your note
A29: Race | B29: IRONMAN 70.3 Texas | C29: Spring 2026 (April as a placeholder). Its logo, small, on the 2026 ring in About. | D29: Yes | E29: Your note

Sheet Open questions
A1: # | B1: Question | C1: Affects | D1: Your answer
A2: 1 | B2: Your portfolio PDF is marked "confidential, intended solely for the recipient". Is it OK to show these projects (photos, renders, numbers) on a public site? | C2: E3–E6, S1a–d, U1–U2 | D2: Yes
A3: 2 | B3: What can be shown publicly about Enovis (photos, layouts, numbers)? | C3: R1, E1, E2 | D3: Yes we can decide later
A4: 3 | B4: Full country list (34 entries counted earlier vs 33 in your note). | C4: Travel map | D4: you cab veify count those should all go on map
A5: 4 | B5: Places lived: confirm cities and years (Lawrence 2014–18; Chicago or Wilmette 2018–19; Milan 2019–21; Dallas 2021–24; Austin since when?). | C5: P1–P6, About | D5: april 2025 to now
A6: 5 | B6: Start / end dates for the MAPEI projects (dry mix plant, palletizer, static mixing, site development, liquid admixtures). | C6: E3–E7 | D6: skip for now maybe just makr placeholers
A7: 6 | B7: Stallion fleet project: 3 or 5 chargers? The portfolio says both. | C7: S1b | D7: 5 chargers
A8: 7 | B8: Site development: Houston (portfolio) while the role was Dallas-based. Confirm, and show it with the dry mix plant as one Houston story? | C8: E5, E3 | D8: I traveled yes from dallas to houston lived in dallas
A9: 8 | B9: $5M liquid admixtures expansion: where, when, any photos? | C9: E7 | D9: yes I have
A10: 9 | B10: Resin Light 1.0 / 2.0 and LED wall art: what they are, materials, years, photos, any code or controller. | C10: M1–M3 | D10: Descriptions received (now in M1–M3). Photos later.
A11: 10 | B11: Which CAD files can you export (dry mix tower, palletizer, static mixer, FSAE car, piano-pedal device)? These become the 3D models. | C11: 3D models | D11: we mguht have to make respresetnations for some not acutal ones. Then show phtoso when we click on them!
A12: 11 | B12: Links to the news coverage of the piano-pedal device. | C12: U2 | D12: yes I can get add dummy ones
A13: 12 | B13: Album years (only the 2025 ones are dated) and the cities for Argentina–Chile–Peru, Mexico, New Mexico, Peru. Colombia album is empty. | C13: F1–F11, Travel | D13: fixed
... A22: 21 | B22: Enovis budget: you changed it to >$20M; your resume still says >$10M. | C22: E1, resume | D22: $10M is fine: reverted to >$10M
A23: 22 | B23: Factory digital twin (A14): what does it model, what is it built with, when, is there a link or screenshots, and is it personal or tied to an employer? | C23: A14, Apps
A24: 23 | B24: About is now a calendar wheel (rings = year, angle = month). Start months for: KU, piano-pedal device, Formula SAE, MAPEI SpA, MAPEI Corp (Chicago and Dallas), OnlyChargeEV, the facility build-out. Only Enovis (April 2025) is known; the rest are placeholders. | C24: About
A25: 24 | B25: Races: was the Austin Marathon the full 26.2 or the half? Which month was IRONMAN 70.3 Texas (April is the placeholder)? | C25: About | D25: Austin Marathon: the full 26.2. IRONMAN month still open (April placeholder).
A26: 25 | B26: Origin card (click "Grant" in About): which email should it show? (The repo is public, so the address will be visible to scrapers; a forwarding address is an option.) Also: send the headshot, and edit the two draft sentences if you like. | C26: About, contact
A27: 26 | B27: Liquid admixtures plant (E7): can you send its 3D model (GLB, like the dry mix plant) or snapshots? It would get the same live model, still and About turntable. | C27: E7, 3D models | D27: Same facility as the dry mix plant: the MAPEI Houston model (v12) is used for it, with the plant building lit.
A28: 27 | B28: The dry mix plant now sits in About (2022 ring, March placeholder) so its 3D tile can turn on hover. Keep it there, and which month did it start? | C28: E3, About
A29: 28 | B29: MAPEI Houston zone names (v12): "Silo & mixing tower", "Production & warehouse" (packaging and the admixtures plant inside), "Offices", "Site". Rename any? | C29: E3, 3D model
A30: 29 | B30: MPOC: your Pascal handoff traces the real floor plan (rooms, names, drawing references). The public repo only uses its proportions and block layout. Do you want the detailed layout shown on the site (it would be public)? | C30: E1, E2, 3D model
A31: 30 | B31: MPOC: where is the additive & subtractive manufacturing lab? It is placed at the east end, behind the offices, as a guess. | C31: E2, 3D model
A32: 31 | B32: MAPEI Houston: where inside the building is the liquid admixtures plant (and any outdoor tanks)? It could get its own zone. | C32: E7, 3D model
A33: 32 | B33: Clean pack & sterilization: should it be its own project tile (it would open the MPOC model with that zone lit), or stay part of the facility build-out? | C33: E1, 3D model
A34: 33 | B34: Pedal photos: the ones you sent are thumbnails; the portfolio copies used are still small (largest 558 px). Larger originals? Also: the photo with the pianist shows her (a teen at the time) and her home; OK on the public site? | C34: U2, photos
A35: 34 | B35: Photos for other projects: send them and they go in the same photo viewer. The portfolio already has Formula SAE photos (car, battery box, motor controller). Add those? | C35: U1, photos | D35: Racecar: cover is the render, the rain photo is in the photo viewer, plus the video link.
A36: 35 | B36: The portfolio has more MAPEI images: the Houston silo tower and plant interior photos, tower CAD, elevation, P&ID, the static mixer (photo and drawing) and the Houston building. Add them to the dry mix, static mixing and site development photo viewers? Larger originals of the palletizer images (345 px) would also look sharper. | C36: E3, E4, E5, E6, photos | D36: Yes: dry mix plant (tower and interior photos) and static mixing (mixer photo and piping drawing). Site development stays as it is.
